<?xml version="1.0" encoding="utf-8"?>
<!-- This URDF was automatically created by SolidWorks to URDF Exporter! Originally created by Stephen Brawner (brawner@gmail.com) 
     Commit Version: 1.6.0-1-g15f4949  Build Version: 1.6.7594.29634
     For more information, please see http://wiki.ros.org/sw_urdf_exporter -->
<robot
  name="segment_follow_ver1">
  <link
    name="base_link">
    <inertial>
      <origin
        xyz="0.010763 0.12575 0.19671"
        rpy="0 0 0" />
      <mass
        value="0.029248" />
      <inertia
        ixx="3.8875E-05"
        ixy="-5.9801E-08"
        ixz="3.066E-09"
        iyy="1.9306E-05"
        iyz="7.6463E-10"
        izz="1.9864E-05" />
    </inertial>
    <visual>
      <origin
        xyz="0 0 0"
        rpy="0 0 0" />
      <geometry>
        <mesh
          filename="package://segment_follow_ver1/meshes/base_link.STL" />
      </geometry>
      <material
        name="">
        <color
          rgba="0.29804 0.29804 0.29804 1" />
      </material>
    </visual>
    <collision>
      <origin
        xyz="0 0 0"
        rpy="0 0 0" />
      <geometry>
        <mesh
          filename="package://segment_follow_ver1/meshes/base_link.STL" />
      </geometry>
    </collision>
  </link>
  <link
    name="sus1">
    <inertial>
      <origin
        xyz="0.024528 -0.0057974 -0.008"
        rpy="0 0 0" />
      <mass
        value="0.0048446" />
      <inertia
        ixx="3.4495E-07"
        ixy="5.1061E-08"
        ixz="1.278E-14"
        iyy="2.3123E-06"
        iyz="2.1948E-14"
        izz="2.0865E-06" />
    </inertial>
    <visual>
      <origin
        xyz="0 0 0"
        rpy="0 0 0" />
      <geometry>
        <mesh
          filename="package://segment_follow_ver1/meshes/sus1.STL" />
      </geometry>
      <material
        name="">
        <color
          rgba="0.79216 0.81961 0.93333 1" />
      </material>
    </visual>
    <collision>
      <origin
        xyz="0 0 0"
        rpy="0 0 0" />
      <geometry>
        <mesh
          filename="package://segment_follow_ver1/meshes/sus1.STL" />
      </geometry>
    </collision>
  </link>
  <joint
    name="sus1r"
    type="revolute">
    <origin
      xyz="0.020949 -0.28148 0.067161"
      rpy="3.1416 -0.5236 1.5708" />
    <parent
      link="base_link" />
    <child
      link="sus1" />
    <axis
      xyz="0 0 0" />
    <limit
      lower="0"
      upper="0"
      effort="0"
      velocity="0" />
  </joint>
  <link
    name="w11">
    <inertial>
      <origin
        xyz="5.2222E-12 0.011 1.8397E-11"
        rpy="0 0 0" />
      <mass
        value="0.0080256" />
      <inertia
        ixx="2.6304E-06"
        ixy="-7.5528E-16"
        ixz="6.5732E-16"
        iyy="9.6877E-07"
        iyz="-1.4033E-15"
        izz="2.6304E-06" />
    </inertial>
    <visual>
      <origin
        xyz="0 0 0"
        rpy="0 0 0" />
      <geometry>
        <mesh
          filename="package://segment_follow_ver1/meshes/w11.STL" />
      </geometry>
      <material
        name="">
        <color
          rgba="0.79216 0.81961 0.93333 1" />
      </material>
    </visual>
    <collision>
      <origin
        xyz="0 0 0"
        rpy="0 0 0" />
      <geometry>
        <mesh
          filename="package://segment_follow_ver1/meshes/w11.STL" />
      </geometry>
    </collision>
  </link>
  <joint
    name="w11r"
    type="continuous">
    <origin
      xyz="0 0 -0.019"
      rpy="1.5708 0 -1.0993" />
    <parent
      link="sus1" />
    <child
      link="w11" />
    <axis
      xyz="0 0 0" />
    <limit
      lower="0"
      upper="0"
      effort="0"
      velocity="0" />
  </joint>
  <link
    name="sus2">
    <inertial>
      <origin
        xyz="0.0245281388862843 -0.00579743458596982 -0.00799999408218524"
        rpy="0 0 0" />
      <mass
        value="0.00484464622012381" />
      <inertia
        ixx="3.44953504540437E-07"
        ixy="5.10613036903035E-08"
        ixz="1.55592500691201E-13"
        iyy="2.31225031988856E-06"
        iyz="4.30376878738603E-14"
        izz="2.0864986737292E-06" />
    </inertial>
    <visual>
      <origin
        xyz="0 0 0"
        rpy="0 0 0" />
      <geometry>
        <mesh
          filename="package://segment_follow_ver1/meshes/sus2.STL" />
      </geometry>
      <material
        name="">
        <color
          rgba="0.792156862745098 0.819607843137255 0.933333333333333 1" />
      </material>
    </visual>
    <collision>
      <origin
        xyz="0 0 0"
        rpy="0 0 0" />
      <geometry>
        <mesh
          filename="package://segment_follow_ver1/meshes/sus2.STL" />
      </geometry>
    </collision>
  </link>
  <joint
    name="sus2r"
    type="revolute">
    <origin
      xyz="0.020949 -0.10396 0.081018"
      rpy="0 -0.5236 -1.5708" />
    <parent
      link="base_link" />
    <child
      link="sus2" />
    <axis
      xyz="0 0 0" />
    <limit
      lower="0"
      upper="0"
      effort="0"
      velocity="0" />
  </joint>
  <link
    name="w12">
    <inertial>
      <origin
        xyz="5.21314935664208E-12 0.0109999999660882 1.84374460143744E-11"
        rpy="0 0 0" />
      <mass
        value="0.00802564595064063" />
      <inertia
        ixx="2.63042675366783E-06"
        ixy="-7.55284350110964E-16"
        ixz="6.57278297069787E-16"
        iyy="9.6877186556785E-07"
        iyz="-1.39968951985772E-15"
        izz="2.63042674933547E-06" />
    </inertial>
    <visual>
      <origin
        xyz="0 0 0"
        rpy="0 0 0" />
      <geometry>
        <mesh
          filename="package://segment_follow_ver1/meshes/w12.STL" />
      </geometry>
      <material
        name="">
        <color
          rgba="0.792156862745098 0.819607843137255 0.933333333333333 1" />
      </material>
    </visual>
    <collision>
      <origin
        xyz="0 0 0"
        rpy="0 0 0" />
      <geometry>
        <mesh
          filename="package://segment_follow_ver1/meshes/w12.STL" />
      </geometry>
    </collision>
  </link>
  <joint
    name="w12r"
    type="continuous">
    <origin
      xyz="0 0 -0.019"
      rpy="1.5708 0 -1.0993" />
    <parent
      link="sus2" />
    <child
      link="w12" />
    <axis
      xyz="0 0 0" />
    <limit
      lower="0"
      upper="0"
      effort="0"
      velocity="0" />
  </joint>
  <link
    name="sus3">
    <inertial>
      <origin
        xyz="0.0245281427339185 -0.00579743476204341 -0.00799999583699243"
        rpy="0 0 0" />
      <mass
        value="0.00484464531506038" />
      <inertia
        ixx="3.44953306450567E-07"
        ixy="5.10613156648366E-08"
        ixz="7.85719483339943E-14"
        iyy="2.31224993634185E-06"
        iyz="3.48701370251376E-14"
        izz="2.08649849059194E-06" />
    </inertial>
    <visual>
      <origin
        xyz="0 0 0"
        rpy="0 0 0" />
      <geometry>
        <mesh
          filename="package://segment_follow_ver1/meshes/sus3.STL" />
      </geometry>
      <material
        name="">
        <color
          rgba="0.792156862745098 0.819607843137255 0.933333333333333 1" />
      </material>
    </visual>
    <collision>
      <origin
        xyz="0 0 0"
        rpy="0 0 0" />
      <geometry>
        <mesh
          filename="package://segment_follow_ver1/meshes/sus3.STL" />
      </geometry>
    </collision>
  </link>
  <joint
    name="sus3r"
    type="revolute">
    <origin
      xyz="0.020949 -0.20472 0.22783"
      rpy="1.5708 1.5708 0" />
    <parent
      link="base_link" />
    <child
      link="sus3" />
    <axis
      xyz="0 0 0" />
    <limit
      lower="0"
      upper="0"
      effort="0"
      velocity="0" />
  </joint>
  <link
    name="w13">
    <inertial>
      <origin
        xyz="5.21754861537715E-12 0.0109999999661513 1.84169901551456E-11"
        rpy="0 0 0" />
      <mass
        value="0.00802564595065764" />
      <inertia
        ixx="2.63042675367367E-06"
        ixy="-7.55267418789561E-16"
        ixz="6.57297037673746E-16"
        iyy="9.6877186557038E-07"
        iyz="-1.40145232605878E-15"
        izz="2.63042674933879E-06" />
    </inertial>
    <visual>
      <origin
        xyz="0 0 0"
        rpy="0 0 0" />
      <geometry>
        <mesh
          filename="package://segment_follow_ver1/meshes/w13.STL" />
      </geometry>
      <material
        name="">
        <color
          rgba="0.792156862745098 0.819607843137255 0.933333333333333 1" />
      </material>
    </visual>
    <collision>
      <origin
        xyz="0 0 0"
        rpy="0 0 0" />
      <geometry>
        <mesh
          filename="package://segment_follow_ver1/meshes/w13.STL" />
      </geometry>
    </collision>
  </link>
  <joint
    name="w13r"
    type="continuous">
    <origin
      xyz="0 0 -0.019"
      rpy="1.5708 0 -1.0993" />
    <parent
      link="sus3" />
    <child
      link="w13" />
    <axis
      xyz="0 0 0" />
    <limit
      lower="0"
      upper="0"
      effort="0"
      velocity="0" />
  </joint>
  <link
    name="con1">
    <inertial>
      <origin
        xyz="0.0150000000000001 -8.32667268468867E-17 -1.52655665885959E-16"
        rpy="0 0 0" />
      <mass
        value="0.00235619449019234" />
      <inertia
        ixx="2.94524311274043E-08"
        ixy="4.86347831101101E-22"
        ixz="1.21907854063494E-21"
        iyy="1.91440802328128E-07"
        iyz="0"
        izz="1.91440802328128E-07" />
    </inertial>
    <visual>
      <origin
        xyz="0 0 0"
        rpy="0 0 0" />
      <geometry>
        <mesh
          filename="package://segment_follow_ver1/meshes/con1.STL" />
      </geometry>
      <material
        name="">
        <color
          rgba="0.792156862745098 0.819607843137255 0.933333333333333 1" />
      </material>
    </visual>
    <collision>
      <origin
        xyz="0 0 0"
        rpy="0 0 0" />
      <geometry>
        <mesh
          filename="package://segment_follow_ver1/meshes/con1.STL" />
      </geometry>
    </collision>
  </link>
  <joint
    name="con1f"
    type="fixed">
    <origin
      xyz="0.011619 -0.19672 0.12534"
      rpy="3.0572 0 0" />
    <parent
      link="base_link" />
    <child
      link="con1" />
    <axis
      xyz="0 0 0" />
  </joint>
  <link
    name="con2">
    <inertial>
      <origin
        xyz="5.55111512312578E-17 0.0511300493614309 -2.22044604925031E-16"
        rpy="0 0 0" />
      <mass
        value="0.00279336263712055" />
      <inertia
        ixx="3.47148573143988E-07"
        ixy="-3.21809896709862E-22"
        ixz="6.26210147309216E-24"
        iyy="3.99316347503688E-08"
        iyz="1.06332602650654E-21"
        izz="3.49420107139763E-07" />
    </inertial>
    <visual>
      <origin
        xyz="0 0 0"
        rpy="0 0 0" />
      <geometry>
        <mesh
          filename="package://segment_follow_ver1/meshes/con2.STL" />
      </geometry>
      <material
        name="">
        <color
          rgba="0.792156862745098 0.819607843137255 0.933333333333333 1" />
      </material>
    </visual>
    <collision>
      <origin
        xyz="0 0 0"
        rpy="0 0 0" />
      <geometry>
        <mesh
          filename="package://segment_follow_ver1/meshes/con2.STL" />
      </geometry>
    </collision>
  </link>
  <joint
    name="con2p"
    type="prismatic">
    <origin
      xyz="-0.003 0 0"
      rpy="0 -1.4864 -1.5708" />
    <parent
      link="con1" />
    <child
      link="con2" />
    <axis
      xyz="0 0 0" />
    <limit
      lower="0"
      upper="0"
      effort="0"
      velocity="0" />
  </joint>
  <link
    name="uni">
    <inertial>
      <origin
        xyz="0.0153755701673791 1.70822661571535E-10 1.70822744838262E-10"
        rpy="0 0 0" />
      <mass
        value="0.00306485478527649" />
      <inertia
        ixx="4.58672113643246E-08"
        ixy="4.47220450271885E-15"
        ixz="-4.47220572149184E-15"
        iyy="3.52620812922611E-07"
        iyz="1.0300750037991E-21"
        izz="3.50349278926836E-07" />
    </inertial>
    <visual>
      <origin
        xyz="0 0 0"
        rpy="0 0 0" />
      <geometry>
        <mesh
          filename="package://segment_follow_ver1/meshes/uni.STL" />
      </geometry>
      <material
        name="">
        <color
          rgba="0.792156862745098 0.819607843137255 0.933333333333333 1" />
      </material>
    </visual>
    <collision>
      <origin
        xyz="0 0 0"
        rpy="0 0 0" />
      <geometry>
        <mesh
          filename="package://segment_follow_ver1/meshes/uni.STL" />
      </geometry>
    </collision>
  </link>
  <joint
    name="uni1r"
    type="revolute">
    <origin
      xyz="0 0.068 0"
      rpy="0 0 1.5708" />
    <parent
      link="con2" />
    <child
      link="uni" />
    <axis
      xyz="0 0 0" />
    <limit
      lower="0"
      upper="0"
      effort="0"
      velocity="0" />
  </joint>
  <link
    name="con3">
    <inertial>
      <origin
        xyz="2.77555756156289E-17 0.0511300493614309 1.66533453693773E-16"
        rpy="0 0 0" />
      <mass
        value="0.00279336263712054" />
      <inertia
        ixx="3.49420107139762E-07"
        ixy="-3.62279923625551E-22"
        ixz="2.21203192017765E-23"
        iyy="3.99316347503688E-08"
        iyz="-9.91888009862822E-22"
        izz="3.47148573143987E-07" />
    </inertial>
    <visual>
      <origin
        xyz="0 0 0"
        rpy="0 0 0" />
      <geometry>
        <mesh
          filename="package://segment_follow_ver1/meshes/con3.STL" />
      </geometry>
      <material
        name="">
        <color
          rgba="0.792156862745098 0.819607843137255 0.933333333333333 1" />
      </material>
    </visual>
    <collision>
      <origin
        xyz="0 0 0"
        rpy="0 0 0" />
      <geometry>
        <mesh
          filename="package://segment_follow_ver1/meshes/con3.STL" />
      </geometry>
    </collision>
  </link>
  <joint
    name="con3p"
    type="revolute">
    <origin
      xyz="0.068 0 0"
      rpy="0 0 1.5708" />
    <parent
      link="uni" />
    <child
      link="con3" />
    <axis
      xyz="0 0 0" />
    <limit
      lower="0"
      upper="0"
      effort="0"
      velocity="0" />
  </joint>
  <link
    name="con4">
    <inertial>
      <origin
        xyz="-0.0150000000000001 -1.11022302462516E-16 2.77555756156289E-17"
        rpy="0 0 0" />
      <mass
        value="0.00235619449019234" />
      <inertia
        ixx="2.94524311274043E-08"
        ixy="-1.1574339151654E-21"
        ixz="-6.82310798372854E-22"
        iyy="1.91440802328128E-07"
        iyz="0"
        izz="1.91440802328128E-07" />
    </inertial>
    <visual>
      <origin
        xyz="0 0 0"
        rpy="0 0 0" />
      <geometry>
        <mesh
          filename="package://segment_follow_ver1/meshes/con4.STL" />
      </geometry>
      <material
        name="">
        <color
          rgba="0.792156862745098 0.819607843137255 0.933333333333333 1" />
      </material>
    </visual>
    <collision>
      <origin
        xyz="0 0 0"
        rpy="0 0 0" />
      <geometry>
        <mesh
          filename="package://segment_follow_ver1/meshes/con4.STL" />
      </geometry>
    </collision>
  </link>
  <joint
    name="con4p"
    type="prismatic">
    <origin
      xyz="0 0.003 0"
      rpy="-0.9827 0 -1.5708" />
    <parent
      link="con3" />
    <child
      link="con4" />
    <axis
      xyz="-1 0 0" />
    <limit
      lower="0"
      upper="0"
      effort="0"
      velocity="0" />
  </joint>
</robot>